Workbook

Sheet Monthly
A1: IDEAL BAKERY
A2: Monthly Payroll
A3: 44287
A4: 30th April 2021 | O4: Other | X4: TAX CALCULATION
E5: Tax | F5: NIS | G5: Basic | H5: Overtime | I5: Other | J5: Bonus | K5: Gross | N5: Union | O5: Loan | P5: Total | Q5: Net | R5: Bank | S5: Account | U5: Gross Earnings | V5: All'ces | W5: Net Earnings | X5: < 36,000 | Y5: 36,001 - 50,000 | Z5: >50001 | AB5: Tax Payable | AF5: Adj TA
A6: Name | B6: Date of Birth | C6: Job Title | D6: Department | E6: Code | F6: Code | G6: Salary | I6: Allce | K6: Salary | L6: PAYE | M6: NIS | N6: Dues | O6: Products | P6: Deduct. | Q6: Pay | S6: Number | AF6: for NIS
A7: PRODUCTION | X7: 0 | Y7: 0.1 | Z7: 0.2 | AB7: EC$
A8: Kennisha Williams | B8: Prince | G8: 2500 | K8: =SUM(G8:J8) -> 2500 | L8: =ROUND(AB8,2) -> 0 | M8: =ROUND(IF(SUM(G8:H8,J8,AF8)*5%>550,550,SUM(G8:H8,J8,AF8)*5%),2) -> 125 | P8: =SUM(L8:O8) -> 125 | Q8: =SUM(K8-P8) -> 2375 | U8: =ROUND(G8*12+H8*12+I8*12+J8*12,0) -> 30000 | V8: 0 | W8: =IF(U8-V8<1,0,U8-V8) -> 30000 | X8: =IF($W8>36000,36000,$W8)*X$7 -> 0 | Y8: =IF($W8>36000,IF($W8>50000,IF($W8>1,36000),$W8-36000),0)*Y$7 -> 0 | Z8: =IF($W8>36000,IF($W8>50000,IF($W8>1,36000),$W8-50000),0)*Z$7 -> 0 | AB8: =SUM(X8:AA8)/12 -> 0 | AF8: EC$ | AL8: 221
A9: Alston Prince | G9: 1815.44 | K9: =SUM(G9:J9) -> 1815.44 | L9: =ROUND(AB9,2) -> 0 | M9: =ROUND(IF(SUM(G9:H9,J9,AF9)*5%>550,550,SUM(G9:H9,J9,AF9)*5%),2) -> 90.77 | P9: =SUM(L9:O9) -> 90.77 | Q9: =SUM(K9-P9) -> 1724.67 | U9: =ROUND(G9*12+H9*12+I9*12+J9*12,0) -> 21785 | V9: 0 | W9: =IF(U9-V9<1,0,U9-V9) -> 21785 | X9: =IF($W9>36000,36000,$W9)*X$7 -> 0 | Y9: =IF($W9>36000,IF($W9>50000,IF($W9>1,36000),$W9-36000),0)*Y$7 -> 0 | Z9: =IF($W9>36000,IF($W9>50000,IF($W9>1,36000),$W9-50000),0)*Z$7 -> 0 | AB9: =SUM(X9:AA9)/12 -> 0 | AK9: 184
A10: Carl Smith | C10: Accounts Clerk | D10: Accounts | G10: 1591.2 | K10: =SUM(G10:J10) -> 1591.2 | L10: =ROUND(AB10,2) -> 0 | M10: =ROUND(IF(SUM(G10:H10,J10,AF10)*5%>550,550,SUM(G10:H10,J10,AF10)*5%),2) -> 79.56 | N10: 25 | P10: =SUM(L10:O10) -> 104.56 | Q10: =SUM(K10-P10) -> 1486.64 | U10: =ROUND(G10*12+H10*12+I10*12+J10*12,0) -> 19094 | V10: 0 | W10: =IF(U10-V10<1,0,U10-V10) -> 19094 | X10: =IF($W10>36000,36000,$W10)*X$7 -> 0 | Y10: =IF($W10>36000,IF($W10>50000,IF($W10>1,36000),$W10-36000),0)*Y$7 -> 0 | Z10: =IF($W10>36000,IF($W10>50000,IF($W10>1,36000),$W10-50000),0)*Z$7 -> 0 | AB10: =SUM(X10:AA10)/12 -> 0 | AK10: 184 | AL10: =AK10+10 -> 194
A11: Dexter Lett | G11: 1200 | K11: =SUM(G11:J11) -> 1200 | L11: =ROUND(AB11,2) -> 0 | M11: =ROUND(IF(SUM(G11:H11,J11,AF11)*5%>550,550,SUM(G11:H11,J11,AF11)*5%),2) -> 60 | P11: =SUM(L11:O11) -> 60 | Q11: =SUM(K11-P11) -> 1140 | U11: =ROUND(G11*12+H11*12+I11*12+J11*12,0) -> 14400 | V11: 0 | W11: =IF(U11-V11<1,0,U11-V11) -> 14400 | X11: =IF($W11>36000,36000,$W11)*X$7 -> 0 | Y11: =IF($W11>36000,IF($W11>50000,IF($W11>1,36000),$W11-36000),0)*Y$7 -> 0 | Z11: =IF($W11>36000,IF($W11>50000,IF($W11>1,36000),$W11-50000),0)*Z$7 -> 0 | AB11: =SUM(X11:AA11)/12 -> 0 | AF11: =IF(I11<500,0,I11-500) -> 0 | AK11: 222
A12: Kenson Baptiste | G12: 1000 | K12: =SUM(G12:J12) -> 1000 | L12: =ROUND(AB12,2) -> 0 | M12: =ROUND(IF(SUM(G12:H12,J12,AF12)*5%>550,550,SUM(G12:H12,J12,AF12)*5%),2) -> 50 | P12: =SUM(L12:O12) -> 50 | Q12: =SUM(K12-P12) -> 950 | U12: =ROUND(G12*12+H12*12+I12*12+J12*12,0) -> 12000 | V12: 0 | W12: =IF(U12-V12<1,0,U12-V12) -> 12000 | X12: =IF($W12>36000,36000,$W12)*X$7 -> 0 | Y12: =IF($W12>36000,IF($W12>50000,IF($W12>1,36000),$W12-36000),0)*Y$7 -> 0 | Z12: =IF($W12>36000,IF($W12>50000,IF($W12>1,36000),$W12-50000),0)*Z$7 -> 0 | AB12: =SUM(X12:AA12)/12 -> 0
A13: Peter Alexis | B13: 23785 | C13: Cleaner | D13: Administration | G13: 934.42 | K13: =SUM(G13:J13) -> 934.42 | L13: =ROUND(AB13,2) -> 0 | M13: =ROUND(IF(SUM(G13:H13,J13,AF13)*5%>550,550,SUM(G13:H13,J13,AF13)*5%),2) -> 46.72 | N13: 15 | P13: =SUM(L13:O13) -> 61.72 | Q13: =SUM(K13-P13) -> 872.7 | U13: =ROUND(G13*12+H13*12+I13*12+J13*12,0) -> 11213 | V13: 0 | W13: =IF(U13-V13<1,0,U13-V13) -> 11213 | X13: =IF($W13>36000,36000,$W13)*X$7 -> 0 | Y13: =IF($W13>36000,IF($W13>50000,IF($W13>1,36000),$W13-36000),0)*Y$7 -> 0 | Z13: =IF($W13>36000,IF($W13>50000,IF($W13>1,36000),$W13-50000),0)*Z$7 -> 0 | AB13: =SUM(X13:AA13)/12 -> 0 | AF13: =IF(I13<500,0,I13-500) -> 0 | AK13: 184 | AL13: =AK13+10 -> 194
A14: Glenderine DeRiggs | B14: 30915 | C14: Office Assistant | D14: Administration | G14: 800 | K14: =SUM(G14:J14) -> 800 | L14: =ROUND(AB14,2) -> 0 | M14: =ROUND(IF(SUM(G14:H14,J14,AF14)*5%>550,550,SUM(G14:H14,J14,AF14)*5%),2) -> 40 | P14: =SUM(L14:O14) -> 40 | Q14: =SUM(K14-P14) -> 760 | U14: =ROUND(G14*12+H14*12+I14*12+J14*12,0) -> 9600 | V14: 0 | W14: =IF(U14-V14<1,0,U14-V14) -> 9600 | X14: =IF($W14>36000,36000,$W14)*X$7 -> 0 | Y14: =IF($W14>36000,IF($W14>50000,IF($W14>1,36000),$W14-36000),0)*Y$7 -> 0 | Z14: =IF($W14>36000,IF($W14>50000,IF($W14>1,36000),$W14-50000),0)*Z$7 -> 0 | AB14: =SUM(X14:AA14)/12 -> 0 | AF14: =IF(I14<500,0,I14-500) -> 0 | AK14: 184 | AL14: =AK14+10 -> 194
A15: Veronica Alexander | K15: =SUM(G15:J15) -> 0 | L15: =ROUND(AB15,2) -> 0 | M15: =ROUND(IF(SUM(G15:H15,J15,AF15)*5%>550,550,SUM(G15:H15,J15,AF15)*5%),2) -> 0 | P15: =SUM(L15:O15) -> 0 | Q15: =SUM(K15-P15) -> 0 | X15: =IF($W15>36000,36000,$W15)*X$7 -> 0 | Y15: =IF($W15>36000,IF($W15>50000,IF($W15>1,36000),$W15-36000),0)*Y$7 -> 0 | Z15: =IF($W15>36000,IF($W15>50000,IF($W15>1,36000),$W15-50000),0)*Z$7 -> 0
B16: 18708 | C16: Director, Technical Services | D16: Technical Services | J16: 0 | K16: =SUM(G16:J16) -> 0 | L16: =ROUND(AB16,2) -> 0 | M16: =ROUND(IF(SUM(G16:H16,J16,AF16)*5%>250,250,SUM(G16:H16,J16,AF16)*5%),2) -> 0 | P16: =SUM(L16:O16) -> 0 | Q16: =K16-P16+#REF! -> #REF! | U16: =ROUND(G16*12+H16*12+I16*12+J16*12,0) -> 0 | V16: =ROUND(E16*100+IF(I16*12>6000,6000,I16*12)+M16*12,0) -> 0 | W16: =IF(U16-V16<1,0,U16-V16) -> 0 | X16: =IF($W16>10000,10000,$W16)*X$7 -> 0 | Y16: =IF($W16>10000,IF($W16>20000,IF($W16>1,10000),$W16-10000),0)*Y$8 -> 0 | Z16: =IF($W16>20000,IF($W16>30000,IF($W16>1,10000),$W16-20000),0)*Z$8 -> 0 | AB16: =SUM(X16:AA16)/12 -> 0 | AF16: =IF(I16<500,0,I16-500) -> 0 | AK16: 273 | AL16: =AK16+10 -> 283
B17: 21501 | C17: Purchasing & Logistics Manager | D17: Purchasing | G17: =SUM(G8:G15) -> 9841.06 | H17: =SUM(H8:H15) -> 0 | I17: =SUM(I8:I15) -> 0 | J17: =SUM(J8:J15) -> 0 | K17: =SUM(K8:K15) -> 9841.06 | L17: =SUM(L8:L15) -> 0 | M17: =SUM(M8:M15) -> 492.05 | N17: =SUM(N8:N15) -> 40 | ... Q17: =SUM(Q8:Q15) -> 9309.01 | AB17: =SUM(X17:AA17)/12 -> 0 | AF17: =IF(I17<500,0,I17-500) -> 0 | AK17: 275 | AL17: =AK17+10 -> 285
A18: ADMINISTRATION | B18: 29697 | C18: Product Controller | D18: Product Management | AF18: =IF(I18<500,0,I18-500) -> 0 | AK18: 476 | AL18: 476
A19: Norris Joseph | G19: 1500 | K19: =SUM(G19:J19) -> 1500 | L19: =ROUND(AB19,2) -> 0 | M19: =ROUND(IF(SUM(G19:H19,J19,AF19)*5%>550,550,SUM(G19:H19,J19,AF19)*5%),2) -> 75 | P19: =SUM(L19:O19) -> 75 | Q19: =SUM(K19-P19) -> 1425 | U19: =ROUND(G19*12+H19*12+I19*12+J19*12,0) -> 18000 | V19: 0 | W19: =IF(U19-V19<1,0,U19-V19) -> 18000 | X19: =IF($W19>36000,36000,$W19)*X$7 -> 0 | Y19: =IF($W19>36000,IF($W19>50000,IF($W19>1,36000),$W19-36000),0)*Y$7 -> 0 | Z19: =IF($W19>36000,IF($W19>50000,IF($W19>1,36000),$W19-50000),0)*Z$7 -> 0 | AB19: =SUM(X19:AA19)/12 -> 0 | AF19: =IF(I19<500,0,I19-500) -> 0 | AK19: 264 | AL19: =AK19+10 -> 274
A20: Gerald Jones | G20: 1450 | K20: =SUM(G20:J20) -> 1450 | L20: =ROUND(AB20,2) -> 0 | M20: =ROUND(IF(SUM(G20:H20,J20,AF20)*5%>550,550,SUM(G20:H20,J20,AF20)*5%),2) -> 72.5 | P20: =SUM(L20:O20) -> 72.5 | Q20: =SUM(K20-P20) -> 1377.5 | U20: =ROUND(G20*12+H20*12+I20*12+J20*12,0) -> 17400 | V20: 0 | W20: =IF(U20-V20<1,0,U20-V20) -> 17400 | X20: =IF($W20>36000,36000,$W20)*X$7 -> 0 | Y20: =IF($W20>36000,IF($W20>50000,IF($W20>1,36000),$W20-36000),0)*Y$7 -> 0 | Z20: =IF($W20>36000,IF($W20>50000,IF($W20>1,36000),$W20-50000),0)*Z$7 -> 0 | AB20: =SUM(X20:AA20)/12 -> 0 | AF20: =IF(I20<500,0,I20-500) -> 0 | AK20: 197 | AL20: =AK20+10 -> 207
G21: =SUM(G19:G20) -> 2950 | H21: =SUM(H19:H20) -> 0 | I21: =SUM(I19:I20) -> 0 | J21: =SUM(J19:J20) -> 0 | K21: =SUM(K19:K20) -> 2950 | L21: =SUM(L19:L20) -> 0 | M21: =SUM(M19:M20) -> 147.5 | N21: =SUM(N19:N20) -> 0 | ... Q21: =SUM(Q19:Q20) -> 2802.5 | AF21: =IF(I21<500,0,I21-500) -> 0
A22: SALES | Q22: =SUM(K22-P22) -> 0 | T22: =SUBTOTAL(9,T16:T19) -> 0 | AK22: 174 | AL22: =AK22+10 -> 184
A23: Oscar Elcock | B23: 30309 | C23: Network Administrator | D23: IT | G23: 1591.2 | K23: =SUM(G23:J23) -> 1591.2 | L23: =ROUND(AB23,2) -> 0 | M23: =ROUND(IF(SUM(G23:H23,J23,AF23)*5%>550,550,SUM(G23:H23,J23,AF23)*5%),2) -> 79.56 | N23: 25 | P23: =SUM(L23:O23) -> 104.56 | Q23: =SUM(K23-P23) -> 1486.64 | U23: =ROUND(G23*12+H23*12+I23*12+J23*12,0) -> 19094 | V23: 0 | W23: =IF(U23-V23<1,0,U23-V23) -> 19094 | X23: =IF($W23>36000,36000,$W23)*X$7 -> 0 | Y23: =IF($W23>36000,IF($W23>50000,IF($W23>1,36000),$W23-36000),0)*Y$7 -> 0 | Z23: =IF($W23>36000,IF($W23>50000,IF($W23>1,36000),$W23-50000),0)*Z$7 -> 0 | AB23: =SUM(X23:AA23)/12 -> 0 | AF23: =IF(I23<500,0,I23-500) -> 0 | AK23: 174 | AL23: =AK23+10 -> 184
A24: Andris Toussaint | G24: 1224 | K24: =SUM(G24:J24) -> 1224 | L24: =SUBTOTAL(9,L23:L23) -> 0 | M24: =ROUND(IF(SUM(G24:H24,J24,AF24)*5%>550,550,SUM(G24:H24,J24,AF24)*5%),2) -> 61.2 | N24: 20 | P24: =SUM(L24:O24) -> 81.2 | Q24: =SUM(K24-P24) -> 1142.8 | U24: =ROUND(G24*12+H24*12+I24*12+J24*12,0) -> 14688 | V24: 0 | W24: =IF(U24-V24<1,0,U24-V24) -> 14688 | X24: =IF($W24>36000,36000,$W24)*X$7 -> 0 | Y24: =IF($W24>36000,IF($W24>50000,IF($W24>1,36000),$W24-36000),0)*Y$7 -> 0 | Z24: =IF($W24>36000,IF($W24>50000,IF($W24>1,36000),$W24-50000),0)*Z$7 -> 0 | AB24: =SUM(X24:AA24)/12 -> 0
A25: Merril Modoo | B25: 22391 | C25: Shipping & Customs Broker Sup. | D25: Shipping | G25: 1530.73 | K25: =SUM(G25:J25) -> 1530.73 | L25: =ROUND(AB25,2) -> 0 | M25: =ROUND(IF(SUM(G25:H25,J25,AF25)*5%>550,550,SUM(G25:H25,J25,AF25)*5%),2) -> 76.54 | N25: 25 | P25: =SUM(L25:O25) -> 101.54 | Q25: =SUM(K25-P25) -> 1429.19 | U25: =ROUND(G25*12+H25*12+I25*12+J25*12,0) -> 18369 | V25: 0 | W25: =IF(U25-V25<1,0,U25-V25) -> 18369 | X25: =IF($W25>36000,36000,$W25)*X$7 -> 0 | Y25: =IF($W25>36000,IF($W25>50000,IF($W25>1,36000),$W25-36000),0)*Y$7 -> 0 | Z25: =IF($W25>36000,IF($W25>50000,IF($W25>1,36000),$W25-50000),0)*Z$7 -> 0 | AB25: =SUM(X25:AA25)/12 -> 0 | AF25: =IF(I25<500,0,I25-500) -> 0 | AK25: 275 | AL25: 273
A26: Onika Phillip | G26: 1000 | K26: =SUM(G26:J26) -> 1000 | L26: =SUBTOTAL(9,L25:L25) -> 0 | M26: =ROUND(IF(SUM(G26:H26,J26,AF26)*5%>550,550,SUM(G26:H26,J26,AF26)*5%),2) -> 50 | P26: =SUM(L26:O26) -> 50 | Q26: =SUM(K26-P26) -> 950 | U26: =ROUND(G26*12+H26*12+I26*12+J26*12,0) -> 12000 | V26: 0 | W26: =IF(U26-V26<1,0,U26-V26) -> 12000
G27: =SUM(G23:G26) -> 5345.93 | H27: =SUM(H23:H26) -> 0 | I27: =SUM(I23:I26) -> 0 | J27: =SUM(J23:J26) -> 0 | K27: =SUM(K23:K26) -> 5345.93 | L27: =SUM(L23:L26) -> 0 | M27: =SUM(M23:M26) -> 267.3 | N27: =SUM(N23:N26) -> 70 | ... Q27: =SUM(Q23:Q26) -> 5008.63
G29: =SUM(G17,G21,G27) -> 18136.99 | H29: =SUM(H17,H21,H27) -> 0 | I29: =SUM(I17,I21,I27) -> 0 | J29: =SUM(J17,J21,J27) -> 0 | K29: =SUM(K17,K21,K27) -> 18136.99 | L29: =SUM(L17,L21,L27) -> 0 | M29: =SUM(M17,M21,M27) -> 906.85 | N29: =SUM(N17,N21,N27) -> 110 | ... Q29: =SUM(Q17,Q21,Q27) -> 17120.14
A30: =A7 -> PRODUCTION | G30: =G17 -> 9841.06 | H30: =H17 -> 0 | I30: =I17 -> 0 | J30: =J17 -> 0 | K30: =K17 -> 9841.06 | L30: =L17 -> 0 | M30: =M17 -> 492.05 | N30: =N17 -> 40 | ... Q30: =Q17 -> 9309.01
A31: =A18 -> ADMINISTRATION | G31: =G21 -> 2950 | H31: =H21 -> 0 | I31: =I21 -> 0 | J31: =J21 -> 0 | K31: =K21 -> 2950 | L31: =L21 -> 0 | M31: =M21 -> 147.5 | N31: =N21 -> 0 | ... Q31: =Q21 -> 2802.5
A32: =A22 -> SALES | G32: =G27 -> 5345.93 | H32: =H27 -> 0 | I32: =I27 -> 0 | J32: =J27 -> 0 | K32: =K27 -> 5345.93 | L32: =L27 -> 0 | M32: =M27 -> 267.3 | N32: =N27 -> 70 | ... Q32: =Q27 -> 5008.63
G33: =SUM(G30:G32) -> 18136.99 | H33: =SUM(H30:H32) -> 0 | I33: =SUM(I30:I32) -> 0 | J33: =SUM(J30:J32) -> 0 | K33: =SUM(K30:K32) -> 18136.99 | L33: =SUM(L30:L32) -> 0 | M33: =SUM(M30:M32) -> 906.85 | N33: =SUM(N30:N32) -> 110 | ... Q33: =SUM(Q30:Q32) -> 17120.14
K37: =K33*6% -> 1088.2194 | M37: =NIS!D31 -> 906.85
R40: =#REF!-Q40 -> #REF!

Sheet Union Dues
A1: IDEAL BAKERY
A2: Monthly Payroll
A3: Union Dues
A4: =Monthly!A4 -> 30th April 2021
A6: Name
A9: =PAYE!A8 -> Kennisha Williams | C9: =Monthly!N8 -> 0
A10: =PAYE!A9 -> Alston Prince | C10: =Monthly!N9 -> 0
A11: =PAYE!A10 -> Carl Smith | C11: =Monthly!N10 -> 25
A12: =PAYE!A11 -> Dexter Lett | C12: =Monthly!N11 -> 0
A13: =PAYE!A12 -> Kenson Baptiste | C13: =Monthly!N12 -> 0
A14: =PAYE!A13 -> Peter Alexis | C14: =Monthly!N13 -> 15
A15: =PAYE!A14 -> Glenderine DeRiggs | C15: =Monthly!N14 -> 0
A16: =PAYE!A15 -> Veronica Alexander | C16: =Monthly!N15 -> 0
A17: =PAYE!A16 -> Norris Joseph | C17: =Monthly!N19 -> 0
A18: =PAYE!A17 -> Gerald Jones | C18: =Monthly!N20 -> 0
A19: =PAYE!A18 -> Oscar Elcock | C19: =Monthly!N23 -> 25
A20: =PAYE!A19 -> Andris Toussaint | C20: =Monthly!N24 -> 20
A21: =PAYE!A20 -> Merril Modoo | C21: =Monthly!N25 -> 25
A22: =PAYE!A21 -> Onika Phillip | C22: =Monthly!N26 -> 0
A24: Total Union Dues | C24: =SUM(C9:C23) -> 110

Sheet 3rdParty
A1: Winfresh Limited
A2: =Monthly!A2 -> Monthly Payroll
A3: St LUCIA
C4: A | G4: B | K4: C | O4: D | S4: E | W4: F | AD4: H | AH4: I | AL4: J | AP4: K | AT4: L | AX4: M | BB4: N | BF4: O | BJ4: P | BN4: Q | BR4: R | BV4: S | CO4: Y
B5: National Farmers Co-operative Credit Union | F5: Bank of Nova Scotia | J5: Bank of Nova Scotia for Capital Life | N5: Caribbean Banking Corporation (RBTT Bank) | R5: First National Bank of St Lucia | V5: First Caribbean International Bank (Barclays) | Z5: First Caribbean International Bank (Barclays) for American Life Insurance | AC5: First Caribbean International Bank (Barclays) for Barbados Mutal Life | AG5: First Caribbean International Bank (Barclays) for Colonial Life Insurance | AK5: First Caribbean International Bank (CIBC) | AO5: Royal Bank of Canada | AS5: Bank of St Lucia Ltd | AW5: St Lucia Civil Service Co-op Credit Union | BA5: Demerara As Society | BE5: FASTCASH | BI5: FICS | BM5: Sagicor | BQ5: St Lucia Civil Service Association | BU5: Choiseul Co-operativeCredit Union | BY5: National Workers Union | CB5: The Mutual Finance Inc. | CE5: Guyana & Trinidad Mutual Life Ins Co Ltd | CH5: Accountant General | CK5: British American Insuarnce Company Limited | CN5: Laborie Co-operative Credit Union | CR5: St Lucia Teachers' Co-operative Credit Union | CU5: UK
CX6: Total
CX7: 3rd Party
A9: Name | B9: Acct No | C9: Location | D9: Amount | F9: Acct No | G9: Location | H9: Amount | J9: Acct No | K9: Location | L9: Amount | N9: Acct No | O9: Location | P9: Amount | R9: Acct No | S9: Location | T9: Amount | V9: Acct No | W9: Location | X9: Amount | Z9: Acct No | AA9: Amount | AC9: Acct No | AD9: Location | AE9: Amount | AG9: Acct No | AH9: Location | AI9: Amount | AK9: Acct No | AL9: Location | AM9: Amount | AO9: Acct No | AP9: Location | AQ9: Amount | AS9: Acct No | AT9: Location | AU9: Amount | AW9: Acct No | AX9: Location | AY9: Amount | BA9: Acct No | BB9: Location | BC9: Amount
A12: Mildred Ochilien | AY12: 1160 | BO12: 295.08 | CX12: =SUM(D12,H12,L12,P12,T12,X12,AA12,AE12,AI12,AM12,AQ12,BC12,BG12,BK12,BO12,BS12,BW12,BZ12,AU12,AY12,CC12,CF12,CI12,CL12,CP12,CS12,CV12) -> 1455.08
A14: Joyce d'Auvergne | CX14: =SUM(D14,H14,L14,P14,T14,X14,AA14,AE14,AI14,AM14,AQ14,BC14,BG14,BK14,BO14,BS14,BW14,BZ14,AU14,AY14,CC14,CF14,CI14,CL14,CP14,CS14,CV14) -> 0
A16: Eardley Barrett | AS16: 913882000 | AT16: Bridge Street | AU16: 6000 | CX16: =SUM(D16,H16,L16,P16,T16,X16,AA16,AE16,AI16,AM16,AQ16,BC16,BG16,BK16,BO16,BS16,BW16,BZ16,AU16,AY16,CC16,CF16,CI16,CL16,CP16,CS16,CV16) -> 6000
A19: Maggie Fadlien | AC19: 1116825 | AE19: 50.06 | AS19: 901034416 | AT19: Nat Housing Auth | AU19: 400 | AY19: =815+65+10+110 -> 1000 | BZ19: 16 | CX19: =SUM(D19,H19,L19,P19,T19,X19,AA19,AE19,AI19,AM19,AQ19,BC19,BG19,BK19,BO19,BS19,BW19,BZ19,AU19,AY19,CC19,CF19,CI19,CL19,CP19,CS19,CV19) -> 1466.06
A20: Paula Joseph | CX20: =SUM(D20,H20,L20,P20,T20,X20,AA20,AE20,AI20,AM20,AQ20,BC20,BG20,BK20,BO20,BS20,BW20,BZ20,AU20,AY20,CC20,CF20,CI20,CL20,CP20,CS20,CV20) -> 0
A21: Vincent Breen | AY21: 280 | CX21: =SUM(D21,H21,L21,P21,T21,X21,AA21,AE21,AI21,AM21,AQ21,BC21,BG21,BK21,BO21,BS21,BW21,BZ21,AU21,AY21,CC21,CF21,CI21,CL21,CP21,CS21,CV21) -> 280
A23: Errol Reid | AS23: 909513000 | AT23: CMMB | AU23: 300 | CX23: =SUM(D23,H23,L23,P23,T23,X23,AA23,AE23,AI23,AM23,AQ23,BC23,BG23,BK23,BO23,BS23,BW23,BZ23,AU23,AY23,CC23,CF23,CI23,CL23,CP23,CS23,CV23) -> 300
A24: Theresa Jn Baptiste | AC24: 1116825 | AE24: 71.57 | BU24: 4121027171 | BV24: BOSL | BW24: 576.82 | CX24: =SUM(D24,H24,L24,P24,T24,X24,AA24,AE24,AI24,AM24,AQ24,BC24,BG24,BK24,BO24,BS24,BW24,BZ24,AU24,AY24,CC24,CF24,CI24,CL24,CP24,CS24,CV24) -> 648.39
A31: Freemont Lawrence | N31: 18003-000-000-24207 | O31: Castries | P31: 600 | AY31: 1970 | CI31: 200 | CX31: =SUM(D31,H31,L31,P31,T31,X31,AA31,AE31,AI31,AM31,AQ31,BC31,BG31,BK31,BO31,BS31,BW31,BZ31,AU31,AY31,CC31,CF31,CI31,CL31,CP31,CS31,CV31) -> 2770
A34: Martin John | F34: 6004325 | G34: Rodney Bay | H34: 455 | AS34: 930341092 | AT34: Castries | AU34: 300 | CX34: =SUM(D34,H34,L34,P34,T34,X34,AA34,AE34,AI34,AM34,AQ34,BC34,BG34,BK34,BO34,BS34,BW34,BZ34,AU34,AY34,CC34,CF34,CI34,CL34,CP34,CS34,CV34) -> 755
A35: Rondell Springer | N35: 11-7362734 | O35: Castries | P35: 1000 | V35: 106785035 | X35: 875 | AS35: 919406000 | AT35: Waterfront, Castries | AU35: 880 | CX35: =SUM(D35,H35,L35,P35,T35,X35,AA35,AE35,AI35,AM35,AQ35,BC35,BG35,BK35,BO35,BS35,BW35,BZ35,AU35,AY35,CC35,CF35,CI35,CL35,CP35,CS35,CV35) -> 2755
A36: Olson Pindar | CN36: 412002352 | CO36: BOSLVieux Fort | CP36: 1200 | CX36: =SUM(D36,H36,L36,P36,T36,X36,AA36,AE36,AI36,AM36,AQ36,BC36,BG36,BK36,BO36,BS36,BW36,BZ36,AU36,AY36,CC36,CF36,CI36,CL36,CP36,CS36,CV36) -> 1200
A38: Agatha Inglis | N38: 11-7317928 | O38: Castries | AC38: 1116825 | AE38: =100+50 -> 150 | AK38: 26826067 | AM38: 930 | AY38: 200 | BS38: 292.81 | CX38: =SUM(D38,H38,L38,P38,T38,X38,AA38,AE38,AI38,AM38,AQ38,BC38,BG38,BK38,BO38,BS38,BW38,BZ38,AU38,AY38,CC38,CF38,CI38,CL38,CP38,CS38,CV38) -> 1572.81
A39: Cyril Joseph | AY39: 600 | BC39: 210.25 | CK39: 100504791 | CL39: 60 | CX39: =SUM(D39,H39,L39,P39,T39,X39,AA39,AE39,AI39,AM39,AQ39,BC39,BG39,BK39,BO39,BS39,BW39,BZ39,AU39,AY39,CC39,CF39,CI39,CL39,CP39,CS39,CV39) -> 870.25
A40: Emran Braville | B40: 05432 | C40: Vieux Fort | D40: 300 | CX40: =SUM(D40,H40,L40,P40,T40,X40,AA40,AE40,AI40,AM40,AQ40,BC40,BG40,BK40,BO40,BS40,BW40,BZ40,AU40,AY40,CC40,CF40,CI40,CL40,CP40,CS40,CV40) -> 300
A41: Marilyn St Rose | J41: 16616 | L41: 606.46 | AG41: 1365310 | AI41: 500 | AS41: 104222571 | AT41: Castries | AU41: 2000 | CX41: =SUM(D41,H41,L41,P41,T41,X41,AA41,AE41,AI41,AM41,AQ41,BC41,BG41,BK41,BO41,BS41,BW41,BZ41,AU41,AY41,CC41,CF41,CI41,CL41,CP41,CS41,CV41) -> 3106.46
A42: Norman Bernard | R42: 335690 | T42: 500 | AY42: 2265 | CX42: =SUM(D42,H42,L42,P42,T42,X42,AA42,AE42,AI42,AM42,AQ42,BC42,BG42,BK42,BO42,BS42,BW42,BZ42,AU42,AY42,CC42,CF42,CI42,CL42,CP42,CS42,CV42) -> 2765
A44: Tessa Boland | F44: 1005226 | G44: Castries | H44: 3480 | CV44: 120 | CX44: =SUM(D44,H44,L44,P44,T44,X44,AA44,AE44,AI44,AM44,AQ44,BC44,BG44,BK44,BO44,BS44,BW44,BZ44,AU44,AY44,CC44,CF44,CI44,CL44,CP44,CS44,CV44) -> 3600
A45: Andre Hippolyte | V45: 106394274 | X45: 1000 | CL45: 166.92 | CX45: =SUM(D45,H45,L45,P45,T45,X45,AA45,AE45,AI45,AM45,AQ45,BC45,BG45,BK45,BO45,BS45,BW45,BZ45,AU45,AY45,CC45,CF45,CI45,CL45,CP45,CS45,CV45) -> 1166.92
A46: Stephen Bruneau | AC46: 1116825 | AE46: 325.69 | AY46: 1195 | BC46: 173.6 | CH46: 1696-01 | CI46: 250 | CX46: =SUM(D46,H46,L46,P46,T46,X46,AA46,AE46,AI46,AM46,AQ46,BC46,BG46,BK46,BO46,BS46,BW46,BZ46,AU46,AY46,CC46,CF46,CI46,CL46,CP46,CS46,CV46) -> 1944.29
A47: Rahjim Albertinie | CX47: =SUM(D47,H47,L47,P47,T47,X47,AA47,AE47,AI47,AM47,AQ47,BC47,BG47,BK47,BO47,BS47,BW47,BZ47,AU47,AY47,CC47,CF47,CI47,CL47,CP47,CS47,CV47) -> 0
A48: Ernest Lubrin | B48: 02258 | C48: Castries | D48: 750 | BC48: 290.96 | CF48: 189.33 | CX48: =SUM(D48,H48,L48,P48,T48,X48,AA48,AE48,AI48,AM48,AQ48,BC48,BG48,BK48,BO48,BS48,BW48,BZ48,AU48,AY48,CC48,CF48,CI48,CL48,CP48,CS48,CV48) -> 1230.29
A53: Cuthbert Joseph | CX53: =SUM(D53,H53,L53,P53,T53,X53,AA53,AE53,AI53,AM53,AQ53,BC53,BG53,BK53,BO53,BS53,BW53,BZ53,AU53,AY53,CC53,CF53,CI53,CL53,CP53,CS53,CV53) -> 0
A55: Theodore Augustin | AY55: 1339.2 | BZ55: 20 | CH55: 113507 | CX55: =SUM(D55,H55,L55,P55,T55,X55,AA55,AE55,AI55,AM55,AQ55,BC55,BG55,BK55,BO55,BS55,BW55,BZ55,AU55,AY55,CC55,CF55,CI55,CL55,CP55,CS55,CV55) -> 1359.2
A60: Winston Giddings | CX60: =SUM(D60,H60,L60,P60,T60,X60,AA60,AE60,AI60,AM60,AQ60,BC60,BG60,BK60,BO60,BS60,BW60,BZ60,AU60,AY60,CC60,CF60,CI60,CL60,CP60,CS60,CV60) -> 0
A63: Arthur St Hill | CX63: =SUM(D63,H63,L63,P63,T63,X63,AA63,AE63,AI63,AM63,AQ63,BC63,BG63,BK63,BO63,BS63,BW63,BZ63,AU63,AY63,CC63,CF63,CI63,CL63,CP63,CS63,CV63) -> 0
A66: Amateus Camille | CX66: =SUM(D66,H66,L66,P66,T66,X66,AA66,AE66,AI66,AM66,AQ66,BC66,BG66,BK66,BO66,BS66,BW66,BZ66,AU66,AY66,CC66,CF66,CI66,CL66,CP66,CS66,CV66) -> 0
CX70: =SUM(D70,H70,L70,P70,T70,X70,AA70,AE70,AI70,AM70,AQ70,BC70,BG70,BK70,BO70,BS70,BW70,BZ70,AU70,AY70,CC70,CF70,CI70,CL70,CP70,CV70) -> 0
D71: =SUM(D11:D70) -> 1050 | H71: =SUM(H11:H70) -> 3935 | L71: =SUM(L11:L70) -> 606.46 | P71: =SUM(P11:P70) -> 1600 | T71: =SUM(T11:T70) -> 500 | X71: =SUM(X11:X70) -> 1875 | AA71: =SUM(AA11:AA70) -> 0 | AE71: =SUM(AE11:AE70) -> 597.32 | AI71: =SUM(AI11:AI70) -> 500 | AM71: =SUM(AM11:AM70) -> 930 | AQ71: =SUM(AQ11:AQ70) -> 0 | AU71: =SUM(AU11:AU70) -> 9880 | AY71: =SUM(AY11:AY70) -> 10009.2 | BC71: =SUM(BC11:BC70) -> 674.81 | BG71: =SUM(BG11:BG70) -> 0 | BK71: =SUM(BK11:BK70) -> 0 | BO71: =SUM(BO11:BO70) -> 295.08 | BS71: =SUM(BS11:BS70) -> 292.81 | BW71: =SUM(BW11:BW70) -> 576.82 | BZ71: =SUM(BZ11:BZ70) -> 36 | CC71: =SUM(CC11:CC70) -> 0 | CF71: =SUM(CF11:CF70) -> 189.33 | CI71: =SUM(CI11:CI70) -> 450 | CL71: =SUM(CL11:CL70) -> 226.92 | CP71: =SUM(CP11:CP70) -> 1200 | CS71: =SUM(CS11:CS70) -> 0 | CV71: =SUM(CV11:CV70) -> 120 | CX71: =SUM(CX11:CX70) -> 35544.75
A73: DOMINICA
B74: National Commercial Bank of Dominica (Roseau) | G74: FASTCASH | J74: SAGICOR | N74: Roseau Co-operative Credit Union Ltd | R74: National Development Foundation of Dominica (NDFD) | V74: Auto Trade Limited
A79: Henry Warner | CX79: =SUM(D79,H79,L79,P79,T79,X79,AA79,AE79,AI79,AM79,AQ79,BC79,BG79,BK79,BO79,BS79,BW79,BZ79,AU79,AY79,CC79,CF79) -> 0
...

Sheet PAYE
A1: IDEAL BAKERY
A2: =Monthly!A4 -> 30th April 2021
A3: PAYE Schedule
A6: Name | B6: Tax Code | C6: Amount
A8: =Monthly!A8 -> Kennisha Williams | C8: =Monthly!L8 -> 0
A9: =Monthly!A9 -> Alston Prince | C9: =Monthly!L9 -> 0
A10: =Monthly!A10 -> Carl Smith | C10: =Monthly!L10 -> 0
A11: =Monthly!A11 -> Dexter Lett | C11: =Monthly!L11 -> 0
A12: =Monthly!A12 -> Kenson Baptiste | C12: =Monthly!L12 -> 0
A13: =Monthly!A13 -> Peter Alexis | C13: =Monthly!L13 -> 0
A14: =Monthly!A14 -> Glenderine DeRiggs | C14: =Monthly!L14 -> 0
A15: =Monthly!A15 -> Veronica Alexander | C15: =Monthly!L15 -> 0
A16: =Monthly!A19 -> Norris Joseph | C16: =Monthly!L19 -> 0
A17: =Monthly!A20 -> Gerald Jones | C17: =Monthly!L20 -> 0
A18: =Monthly!A23 -> Oscar Elcock | C18: =Monthly!L23 -> 0
A19: =Monthly!A24 -> Andris Toussaint | C19: =Monthly!L24 -> 0
A20: =Monthly!A25 -> Merril Modoo | C20: =Monthly!L25 -> 0
A21: =Monthly!A26 -> Onika Phillip | C21: =Monthly!L26 -> 0
C24: =SUM(C8:C21) -> 0

Sheet NIS
A1: Ideal Bakery
A2: =Monthly!A4 -> 30th April 2021
A3: NIS Schedule
C4: Employer | D4: Employee
A5: Name | B5: NIS No. | C5: Contribution | D5: Contribution | E5: Total
A6: =Monthly!A7 -> PRODUCTION
A7: =Monthly!A8 -> Kennisha Williams | C7: =Monthly!K8*6% -> 150 | D7: =Monthly!M8 -> 125 | E7: =C7+D7 -> 275
A8: =Monthly!A9 -> Alston Prince | C8: =Monthly!K9*6% -> 108.9264 | D8: =Monthly!M9 -> 90.77 | E8: =C8+D8 -> 199.6964
A9: =Monthly!A10 -> Carl Smith | C9: =Monthly!K10*6% -> 95.472 | D9: =Monthly!M10 -> 79.56 | E9: =C9+D9 -> 175.032
A10: =Monthly!A11 -> Dexter Lett | C10: =Monthly!K11*6% -> 72 | D10: =Monthly!M11 -> 60 | E10: =C10+D10 -> 132
A11: =Monthly!A12 -> Kenson Baptiste | C11: =Monthly!K12*6% -> 60 | D11: =Monthly!M12 -> 50 | E11: =C11+D11 -> 110
A12: =Monthly!A13 -> Peter Alexis | C12: =Monthly!K13*6% -> 56.0652 | D12: =Monthly!M13 -> 46.72 | E12: =C12+D12 -> 102.7852
A13: =Monthly!A14 -> Glenderine DeRiggs | C13: =Monthly!K14*6% -> 48 | D13: =Monthly!M14 -> 40 | E13: =C13+D13 -> 88
A14: =Monthly!A15 -> Veronica Alexander | C14: =Monthly!K15*6% -> 0 | D14: =Monthly!M15 -> 0 | E14: =C14+D14 -> 0
C15: =SUM(C7:C14) -> 590.4636 | D15: =SUM(D7:D14) -> 492.05 | E15: =SUM(E7:E14) -> 1082.5136
A16: ADMINISTRATION
A18: =Monthly!A19 -> Norris Joseph | C18: =Monthly!K19*6% -> 90 | D18: =Monthly!M19 -> 75 | E18: =C18+D18 -> 165
A19: =Monthly!A20 -> Gerald Jones | C19: =Monthly!K20*6% -> 87 | D19: =Monthly!M20 -> 72.5 | E19: =C19+D19 -> 159.5
C20: =SUM(C18:C19) -> 177 | D20: =SUM(D18:D19) -> 147.5 | E20: =SUM(E18:E19) -> 324.5
A22: SALES
A23: =Monthly!A23 -> Oscar Elcock | C23: =Monthly!K23*6% -> 95.472 | D23: =Monthly!M23 -> 79.56 | E23: =C23+D23 -> 175.032
A24: =Monthly!A24 -> Andris Toussaint | C24: =Monthly!K24*6% -> 73.44 | D24: =Monthly!M24 -> 61.2 | E24: =C24+D24 -> 134.64
A25: =Monthly!A25 -> Merril Modoo | C25: =Monthly!K25*6% -> 91.8438 | D25: =Monthly!M25 -> 76.54 | E25: =C25+D25 -> 168.3838
A26: =Monthly!A26 -> Onika Phillip | C26: =Monthly!K26*6% -> 60 | D26: =Monthly!M26 -> 50 | E26: =C26+D26 -> 110
C27: =SUM(C23:C26) -> 320.7558 | D27: =SUM(D23:D26) -> 267.3 | E27: =SUM(E23:E26) -> 588.0558
A31: Total NIS Due | C31: =SUM(C15,C20,C27) -> 1088.2194 | D31: =SUM(D15,D20,D27) -> 906.85 | E31: =SUM(E15,E20,E27) -> 1995.0694

Sheet Journal
A1: IDEAL BAKERY
A2: JOURNAL ENTRIES
A4: Date | D4: =Monthly!A4 -> 30th April 2021
A5: PARTICULARS | B5: New Account Number | C5: DEBIT | D5: CREDIT
C6: XCD$ | D6: XCD$
A7: PRODUCTION
A8: Salaries | C8: =Monthly!G17 -> 9841.06
A9: Employer NIS Contribution | C9: =NIS!C15 -> 590.4636
A10: Overtime | C10: =Monthly!H17 -> 0
A11: Other Allowance | C11: =Monthly!I17 -> 0
A12: Bonus | C12: =Monthly!J17 -> 0
A13: ADMINISTRATION
A14: Salaries | C14: =Monthly!G21 -> 2950
A15: Employer NIS Contribution | C15: =NIS!C20 -> 177
A16: Overtime | C16: =Monthly!H21 -> 0
A17: Other Allowance | C17: =Monthly!I21 -> 0
A18: Bonus | C18: =Monthly!J21 -> 0
A19: SALES
A20: Salaries | C20: =Monthly!G27 -> 5345.93
A21: Employer NIS Contribution | C21: =NIS!C27 -> 320.7558
A22: Overtime | C22: =Monthly!H27 -> 0
A23: Other Allowance | C23: =Monthly!I27 -> 0
A24: Bonus | C24: =Monthly!J27 -> 0
A26: Salaries & Wages Control | D26: =Monthly!Q33 -> 17120.14
A27: PAYE Control | D27: =Monthly!L33 -> 0
A28: NIS Control | D28: =NIS!E31 -> 1995.0694
A29: Creditors Deduction | D29: =Monthly!O33 -> 0
A30: Union Dues | D30: =Monthly!N33 -> 110
C33: =SUM(C8:C32) -> 19225.209 | D33: =SUM(D8:D32) -> 19225.209
B36: NIC
B37: PAYE
B38: THIRD PARTY
J79: =H77-J77 -> 0

Sheet Third Party Control
A1: IDEAL BAKERY
A2: Monthly Payroll
A3: Credit Deductions
A4: =Monthly!A4 -> 30th April 2021
A6: Name
A9: =PAYE!A8 -> Kennisha Williams | C9: =Monthly!O8 -> 0
A10: =PAYE!A9 -> Alston Prince | C10: =Monthly!O9 -> 0
A11: =PAYE!A10 -> Carl Smith | C11: =Monthly!O10 -> 0
A12: =PAYE!A11 -> Dexter Lett | C12: =Monthly!O11 -> 0
A13: =PAYE!A12 -> Kenson Baptiste | C13: =Monthly!O12 -> 0
A14: =PAYE!A13 -> Peter Alexis | C14: =Monthly!O13 -> 0
A15: =PAYE!A14 -> Glenderine DeRiggs | C15: =Monthly!O14 -> 0
A16: =PAYE!A15 -> Veronica Alexander | C16: =Monthly!O15 -> 0
A17: =PAYE!A16 -> Norris Joseph | C17: =Monthly!O19 -> 0
A18: =PAYE!A17 -> Gerald Jones | C18: =Monthly!O20 -> 0
A19: =PAYE!A18 -> Oscar Elcock | C19: =Monthly!O23 -> 0
A20: =PAYE!A19 -> Andris Toussaint | C20: =Monthly!O24 -> 0
A21: =PAYE!A20 -> Merril Modoo | C21: =Monthly!O25 -> 0
A22: =PAYE!A21 -> Onika Phillip | C22: =Monthly!O26 -> 0
A24: Total Creditors | C24: =SUM(C9:C23) -> 0
C27: =Monthly!O33 -> 0

Sheet Pay slips
B2: EMPLOYEE NAME | C2: PAYROLL DATE
B3: =Monthly!A8 -> Kennisha Williams | C3: =Monthly!A4 -> 30th April 2021 | F3: IDEAL BAKERY
F4: BELMONT ; ST GEORGES'S
F5: GRENADA
C9: PAYMENTS | E9: DEDUCTIONS
C11: Basic | D11: =Monthly!G8 -> 2500 | E11: PAYE | F11: =Monthly!L8 -> 0
C12: Overtime | D12: =Monthly!H8 -> 0 | E12: NIS | F12: =Monthly!M8 -> 125
C13: Other Allow. | D13: =Monthly!I7 -> 0 | E13: Union Dues | F13: =Monthly!O8 -> 0
C14: Bonus | D14: =Monthly!J8 -> 0 | E14: Credit Deduction | F14: =Monthly!N8 -> 0
C17: Gross Pay | D17: =SUM(D11:D15) -> 2500 | E17: Total Deductions | F17: =SUM(F11:F15) -> 125
C20: NET PAY | D20: =D17-F17 -> 2375
B26: EMPLOYEE NAME | C26: PAYROLL DATE
B27: =Monthly!A9 -> Alston Prince | C27: =Monthly!A4 -> 30th April 2021 | F27: IDEAL BAKERY
F28: BELMONT ; ST GEORGES'S
F29: GRENADA
C33: PAYMENTS | E33: DEDUCTIONS
C35: Basic | D35: =Monthly!G9 -> 1815.44 | E35: PAYE | F35: =Monthly!L9 -> 0
C36: Overtime | D36: =Monthly!H9 -> 0 | E36: NIS | F36: =Monthly!M9 -> 90.77
C37: Other Allow. | D37: =Monthly!I9 -> 0 | E37: Union Dues | F37: =Monthly!N9 -> 0
C38: Bonus | D38: =Monthly!J9 -> 0 | E38: Credit Deduction | F38: =Monthly!O9 -> 0
E39: Other | F39: =Monthly!O11 -> 0
C41: Gross Pay | D41: =SUM(D35:D39) -> 1815.44 | E41: Total Deductions | F41: =SUM(F35:F39) -> 90.77
C44: NET PAY | D44: =D41-F41 -> 1724.67
B50: EMPLOYEE NAME | C50: PAYROLL DATE
B51: =Monthly!A10 -> Carl Smith | C51: =Monthly!A4 -> 30th April 2021 | F51: IDEAL BAKERY
F52: BELMONT ; ST GEORGES'S
F53: GRENADA
C57: PAYMENTS | E57: DEDUCTIONS
C59: Basic | D59: =Monthly!G10 -> 1591.2 | E59: PAYE | F59: =Monthly!L10 -> 0
C60: Overtime | D60: =Monthly!H10 -> 0 | E60: NIS | F60: =Monthly!M10 -> 79.56
C61: Other Allow. | D61: =Monthly!I10 -> 0 | E61: Union Dues | F61: =Monthly!N10 -> 25
C62: Bonus | D62: =Monthly!J10 -> 0 | E62: Credit Deduction | F62: =Monthly!O10 -> 0
E63: Other | F63: =Monthly!O21 -> 0
C65: Gross Pay | D65: =SUM(D59:D63) -> 1591.2 | E65: Total Deductions | F65: =SUM(F59:F63) -> 104.56
C68: NET PAY | D68: =D65-F65 -> 1486.64
B74: EMPLOYEE NAME | C74: PAYROLL DATE
B75: =Monthly!A11 -> Dexter Lett | C75: =Monthly!A4 -> 30th April 2021 | F75: IDEAL BAKERY
F76: BELMONT ; ST GEORGES'S
F77: GRENADA
C81: PAYMENTS | E81: DEDUCTIONS
...
